Traceback (most recent call last):
  File "/Users/ggeorg02/opt/miniconda3/envs/jb2023/lib/python3.11/site-packages/jupyter_cache/executors/utils.py", line 58, in single_nb_execution
    executenb(
  File "/Users/ggeorg02/opt/miniconda3/envs/jb2023/lib/python3.11/site-packages/nbclient/client.py", line 1265, in execute
    return NotebookClient(nb=nb, resources=resources, km=km, **kwargs).execute()
           ^^^^^^^^^^^^^^^^^^^^^^^^^^^^^^^^^^^^^^^^^^^^^^^^^^^^^^^^^^^^^^^^^^^^^
  File "/Users/ggeorg02/opt/miniconda3/envs/jb2023/lib/python3.11/site-packages/jupyter_core/utils/__init__.py", line 166, in wrapped
    return loop.run_until_complete(inner)
           ^^^^^^^^^^^^^^^^^^^^^^^^^^^^^^
  File "/Users/ggeorg02/opt/miniconda3/envs/jb2023/lib/python3.11/asyncio/base_events.py", line 650, in run_until_complete
    return future.result()
           ^^^^^^^^^^^^^^^
  File "/Users/ggeorg02/opt/miniconda3/envs/jb2023/lib/python3.11/contextlib.py", line 222, in __aexit__
    await self.gen.athrow(typ, value, traceback)
  File "/Users/ggeorg02/opt/miniconda3/envs/jb2023/lib/python3.11/site-packages/nbclient/client.py", line 648, in async_setup_kernel
    yield
  File "/Users/ggeorg02/opt/miniconda3/envs/jb2023/lib/python3.11/site-packages/nbclient/client.py", line 703, in async_execute
    await self.async_execute_cell(
  File "/Users/ggeorg02/opt/miniconda3/envs/jb2023/lib/python3.11/site-packages/nbclient/client.py", line 1021, in async_execute_cell
    await self._check_raise_for_error(cell, cell_index, exec_reply)
  File "/Users/ggeorg02/opt/miniconda3/envs/jb2023/lib/python3.11/site-packages/nbclient/client.py", line 915, in _check_raise_for_error
    raise CellExecutionError.from_cell_and_msg(cell, exec_reply_content)
nbclient.exceptions.CellExecutionError: An error occurred while executing the following cell:
------------------
import pandas as pd
import matplotlib.pyplot as plt
import psycopg2
import json
import urllib.parse

%load_ext sql
%config SqlMagic.displaylimit = 20
%config SqlMagic.autolimit = 30

with open('credentials.json') as f:
    login = json.load(f)
    
username = login['user']
password = urllib.parse.quote(login['password'])
host = login['host']
port = login['port']
------------------

[0;31m---------------------------------------------------------------------------[0m
[0;31mModuleNotFoundError[0m                       Traceback (most recent call last)
Cell [0;32mIn[1], line 2[0m
[1;32m      1[0m [38;5;28;01mimport[39;00m [38;5;21;01mpandas[39;00m [38;5;28;01mas[39;00m [38;5;21;01mpd[39;00m
[0;32m----> 2[0m [38;5;28;01mimport[39;00m [38;5;21;01mmatplotlib[39;00m[38;5;21;01m.[39;00m[38;5;21;01mpyplot[39;00m [38;5;28;01mas[39;00m [38;5;21;01mplt[39;00m
[1;32m      3[0m [38;5;28;01mimport[39;00m [38;5;21;01mpsycopg2[39;00m
[1;32m      4[0m [38;5;28;01mimport[39;00m [38;5;21;01mjson[39;00m

[0;31mModuleNotFoundError[0m: No module named 'matplotlib'
ModuleNotFoundError: No module named 'matplotlib'

