Traceback (most recent call last):
  File "/Users/ggeorg02/opt/miniconda3/envs/jb2023/lib/python3.11/site-packages/jupyter_cache/executors/utils.py", line 58, in single_nb_execution
    executenb(
  File "/Users/ggeorg02/opt/miniconda3/envs/jb2023/lib/python3.11/site-packages/nbclient/client.py", line 1265, in execute
    return NotebookClient(nb=nb, resources=resources, km=km, **kwargs).execute()
           ^^^^^^^^^^^^^^^^^^^^^^^^^^^^^^^^^^^^^^^^^^^^^^^^^^^^^^^^^^^^^^^^^^^^^
  File "/Users/ggeorg02/opt/miniconda3/envs/jb2023/lib/python3.11/site-packages/jupyter_core/utils/__init__.py", line 166, in wrapped
    return loop.run_until_complete(inner)
           ^^^^^^^^^^^^^^^^^^^^^^^^^^^^^^
  File "/Users/ggeorg02/opt/miniconda3/envs/jb2023/lib/python3.11/asyncio/base_events.py", line 650, in run_until_complete
    return future.result()
           ^^^^^^^^^^^^^^^
  File "/Users/ggeorg02/opt/miniconda3/envs/jb2023/lib/python3.11/contextlib.py", line 222, in __aexit__
    await self.gen.athrow(typ, value, traceback)
  File "/Users/ggeorg02/opt/miniconda3/envs/jb2023/lib/python3.11/site-packages/nbclient/client.py", line 648, in async_setup_kernel
    yield
  File "/Users/ggeorg02/opt/miniconda3/envs/jb2023/lib/python3.11/site-packages/nbclient/client.py", line 703, in async_execute
    await self.async_execute_cell(
  File "/Users/ggeorg02/opt/miniconda3/envs/jb2023/lib/python3.11/site-packages/nbclient/client.py", line 1021, in async_execute_cell
    await self._check_raise_for_error(cell, cell_index, exec_reply)
  File "/Users/ggeorg02/opt/miniconda3/envs/jb2023/lib/python3.11/site-packages/nbclient/client.py", line 915, in _check_raise_for_error
    raise CellExecutionError.from_cell_and_msg(cell, exec_reply_content)
nbclient.exceptions.CellExecutionError: An error occurred while executing the following cell:
------------------
import os
import json
import urllib.parse
from py2neo import Graph

with open('credentials_neo4j.json') as f:
    login = json.load(f)

username = login['username']
password = urllib.parse.quote(login['password'])
host = login['host']
url = "neo4j+s://{}".format(host)

# This is our neo4j Connection Object:
graph = Graph(uri = url,
              user = username,
              password = password,
             secure=True,
             routing=True)

# Your query
most = graph.run("""MATCH (m:Movie) RETURN m.title LIMIT 1""").data()
print(most)
------------------

[0;31m---------------------------------------------------------------------------[0m
[0;31mModuleNotFoundError[0m                       Traceback (most recent call last)
Cell [0;32mIn[1], line 4[0m
[1;32m      2[0m [38;5;28;01mimport[39;00m [38;5;21;01mjson[39;00m
[1;32m      3[0m [38;5;28;01mimport[39;00m [38;5;21;01murllib[39;00m[38;5;21;01m.[39;00m[38;5;21;01mparse[39;00m
[0;32m----> 4[0m [38;5;28;01mfrom[39;00m [38;5;21;01mpy2neo[39;00m [38;5;28;01mimport[39;00m Graph
[1;32m      6[0m [38;5;28;01mwith[39;00m [38;5;28mopen[39m([38;5;124m'[39m[38;5;124mcredentials_neo4j.json[39m[38;5;124m'[39m) [38;5;28;01mas[39;00m f:
[1;32m      7[0m     login [38;5;241m=[39m json[38;5;241m.[39mload(f)

[0;31mModuleNotFoundError[0m: No module named 'py2neo'
ModuleNotFoundError: No module named 'py2neo'

